Workbook

Sheet Orçamento
B3: [ PLANILHA ORÇAMENTO FAMILIAR ] - LANÇAMENTOS DE VALORES
C5: JANEIRO | D5: FEVEREIRO | E5: MARÇO | F5: ABRIL | G5: MAIO | H5: JUNHO | I5: JULHO | J5: AGOSTO | K5: SETEMBRO | L5: OUTUBRO | M5: NOVEMBRO | N5: DEZEMBRO | O5: TOTAL | P5: TENDÊNCIA
B6: RECEITAS | C6: =C12 -> 735 | D6: =D12 -> 830 | E6: =E12 -> 700 | F6: =F12 -> 750 | G6: =G12 -> 630 | H6: =H12 -> 0 | I6: =I12 -> 0 | J6: =J12 -> 0 | ... N6: =N12 -> 0 | O6: =SUM(C6:N6) -> 3645
B7: DESPESAS | C7: =C22+C34+C43+C50+C60+C72+C82+C88 -> 452 | D7: =D22+D34+D43+D50+D60+D72+D82+D88 -> 392 | E7: =E22+E34+E43+E50+E60+E72+E82+E88 -> 745 | F7: =F22+F34+F43+F50+F60+F72+F82+F88 -> 330 | G7: =G22+G34+G43+G50+G60+G72+G82+G88 -> 200 | H7: =H22+H34+H43+H50+H60+H72+H82+H88 -> 0 | I7: =I22+I34+I43+I50+I60+I72+I82+I88 -> 0 | J7: =J22+J34+J43+J50+J60+J72+J82+J88 -> 0 | ... N7: =N22+N34+N43+N50+N60+N72+N82+N88 -> 0 | O7: =SUM(C7:N7) -> 2119
B8: SALDO MENSAL | C8: =C6-C7 -> 283 | D8: =D6-D7 -> 438 | E8: =E6-E7 -> -45 | F8: =F6-F7 -> 420 | G8: =G6-G7 -> 430 | H8: =H6-H7 -> 0 | I8: =I6-I7 -> 0 | J8: =J6-J7 -> 0 | ... O8: =O6-O7 -> 1526
B9: SALDO ACUMULADO | C9: =C8 -> 283 | D9: =C9+D8 -> 721 | E9: =D9+E8 -> 676 | F9: =E9+F8 -> 1096 | G9: =F9+G8 -> 1526 | H9: =G9+H8 -> 1526 | I9: =H9+I8 -> 1526 | J9: =I9+J8 -> 1526 | K9: =J9+K8 -> 1526 | ... N9: =M9+N8 -> 1526 | O9: =N9 -> 1526
B11: Descrição de Receitas
B12: COMPOSIÇÃO RECEITA | C12: =SUM(C13:C18) -> 735 | D12: =SUM(D13:D18) -> 830 | E12: =SUM(E13:E18) -> 700 | F12: =SUM(F13:F18) -> 750 | G12: =SUM(G13:G18) -> 630 | H12: =SUM(H13:H18) -> 0 | I12: =SUM(I13:I18) -> 0 | J12: =SUM(J13:J18) -> 0 | ... O12: =SUM(O13:O18) -> 3645
B13: Salários | C13: 180 | D13: 200 | E13: 250 | F13: 250 | G13: 250 | O13: =SUM(C13:N13) -> 1130 | P13: =IFERROR(O13/$O$12,0) -> 0.31001372
B14: 13º. Salário | C14: 0 | D14: 180 | O14: =SUM(C14:N14) -> 180 | P14: =IFERROR(O14/$O$12,0) -> 0.049382716
B15: Férias | C15: 80 | D15: 0 | F15: 250 | O15: =SUM(C15:N15) -> 330 | P15: =IFERROR(O15/$O$12,0) -> 0.090534979
B16: Retirada de Poupança | C16: 120 | D16: 80 | E16: 150 | F16: 100 | G16: 180 | O16: =SUM(C16:N16) -> 630 | P16: =IFERROR(O16/$O$12,0) -> 0.17283951
B17: Retirada de Aplicações | C17: 150 | D17: 120 | E17: 100 | O17: =SUM(C17:N17) -> 370 | P17: =IFERROR(O17/$O$12,0) -> 0.10150892
B18: Outros | C18: 205 | D18: 250 | E18: 200 | F18: 150 | G18: 200 | O18: =SUM(C18:N18) -> 1005 | P18: =IFERROR(O18/$O$12,0) -> 0.27572016
B20: Descrição de Despesas por Categoria
B21: % EM RELAÇÃO À RECEITA | C21: =IFERROR(C22/C$6,0) -> 0.27210884 | D21: =IFERROR(D22/D$6,0) -> 0.28915663 | E21: =IFERROR(E22/E$6,0) -> 0.91428571 | F21: =IFERROR(F22/F$6,0) -> 0.28666667 | G21: =IFERROR(G22/G$6,0) -> 0.20634921 | H21: =IFERROR(H22/H$6,0) -> 0 | I21: =IFERROR(I22/I$6,0) -> 0 | J21: =IFERROR(J22/J$6,0) -> 0 | ... O21: =IFERROR(O22/O$6,0) -> 0.3909465
B22: HABITAÇÃO | C22: =SUM(C23:C31) -> 200 | D22: =SUM(D23:D31) -> 240 | E22: =SUM(E23:E31) -> 640 | F22: =SUM(F23:F31) -> 215 | G22: =SUM(G23:G31) -> 130 | H22: =SUM(H23:H31) -> 0 | I22: =SUM(I23:I31) -> 0 | J22: =SUM(J23:J31) -> 0 | ... O22: =SUM(O23:O31) -> 1425
B23: Aluguel/Prestação | C23: 100 | D23: 100 | E23: 150 | F23: 100 | G23: 50 | O23: =SUM(C23:N23) -> 500 | P23: =IFERROR(O23/$O$22,0) -> 0.35087719
B24: Condomínio | D24: 50 | E24: 50 | O24: =SUM(C24:N24) -> 100 | P24: =IFERROR(O24/$O$22,0) -> 0.070175439
B25: IPTU | C25: 50 | E25: 50 | F25: 45 | O25: =SUM(C25:N25) -> 145 | P25: =IFERROR(O25/$O$22,0) -> 0.10175439
B26: Luz | E26: 300 | O26: =SUM(C26:N26) -> 300 | P26: =IFERROR(O26/$O$22,0) -> 0.21052632
B27: Telefones | O27: =SUM(C27:N27) -> 0 | P27: =IFERROR(O27/$O$22,0) -> 0
B28: TV por Assinatura | C28: 50 | D28: 50 | E28: 50 | F28: 50 | G28: 50 | O28: =SUM(C28:N28) -> 250 | P28: =IFERROR(O28/$O$22,0) -> 0.1754386
B29: Internet | O29: =SUM(C29:N29) -> 0 | P29: =IFERROR(O29/$O$22,0) -> 0
B30: Empregada | D30: 40 | E30: 40 | F30: 20 | G30: 30 | O30: =SUM(C30:N30) -> 130 | P30: =IFERROR(O30/$O$22,0) -> 0.09122807
B31: Outros | O31: =SUM(C31:N31) -> 0 | P31: =IFERROR(O31/$O$22,0) -> 0
B33: % EM RELAÇÃO À RECEITA | C33: =IFERROR(C34/C$6,0) -> 0.016326531 | D33: =IFERROR(D34/D$6,0) -> 0.012048193 | E33: =IFERROR(E34/E$6,0) -> 0.035714286 | F33: =IFERROR(F34/F$6,0) -> 0.033333333 | G33: =IFERROR(G34/G$6,0) -> 0.015873016 | H33: =IFERROR(H34/H$6,0) -> 0 | I33: =IFERROR(I34/I$6,0) -> 0 | J33: =IFERROR(J34/J$6,0) -> 0 | ... O33: =IFERROR(O34/O$6,0) -> 0.022496571
B34: EDUCAÇÃO | C34: =SUM(C35:C40) -> 12 | D34: =SUM(D35:D40) -> 10 | E34: =SUM(E35:E40) -> 25 | F34: =SUM(F35:F40) -> 25 | G34: =SUM(G35:G40) -> 10 | H34: =SUM(H35:H40) -> 0 | I34: =SUM(I35:I40) -> 0 | J34: =SUM(J35:J40) -> 0 | ... O34: =SUM(O35:O40) -> 82
B35: Faculdade | O35: =SUM(C35:N35) -> 0 | P35: =IFERROR(O35/$O$34,0) -> 0
B36: Curso de Idiomas | C36: 12 | E36: 15 | F36: 15 | O36: =SUM(C36:N36) -> 42 | P36: =IFERROR(O36/$O$34,0) -> 0.51219512
B37: Material Escolar | D37: 10 | O37: =SUM(C37:N37) -> 10 | P37: =IFERROR(O37/$O$34,0) -> 0.12195122
B38: Cursos profissionalizantes | E38: 10 | F38: 10 | G38: 10 | O38: =SUM(C38:N38) -> 30 | P38: =IFERROR(O38/$O$34,0) -> 0.36585366
B39: Escola filho | O39: =SUM(C39:N39) -> 0 | P39: =IFERROR(O39/$O$34,0) -> 0
B40: Outros | O40: =SUM(C40:N40) -> 0 | P40: =IFERROR(O40/$O$34,0) -> 0
B42: % EM RELAÇÃO À RECEITA | C42: =IFERROR(C43/C$6,0) -> 0.020408163 | D42: =IFERROR(D43/D$6,0) -> 0.024096386 | E42: =IFERROR(E43/E$6,0) -> 0.028571429 | F42: =IFERROR(F43/F$6,0) -> 0.026666667 | G42: =IFERROR(G43/G$6,0) -> 0.015873016 | H42: =IFERROR(H43/H$6,0) -> 0 | I42: =IFERROR(I43/I$6,0) -> 0 | J42: =IFERROR(J43/J$6,0) -> 0 | ... O42: =IFERROR(O43/O$6,0) -> 0.023319616
B43: SAÚDE | C43: =SUM(C44:C47) -> 15 | D43: =SUM(D44:D47) -> 20 | E43: =SUM(E44:E47) -> 20 | F43: =SUM(F44:F47) -> 20 | G43: =SUM(G44:G47) -> 10 | H43: =SUM(H44:H47) -> 0 | I43: =SUM(I44:I47) -> 0 | J43: =SUM(J44:J47) -> 0 | ... O43: =SUM(O44:O47) -> 85
B44: Plano de Saúde | O44: =SUM(C44:N44) -> 0 | P44: =IFERROR(O44/$O$43,0) -> 0
B45: Dentista | C45: 15 | E45: 20 | F45: 20 | O45: =SUM(C45:N45) -> 55 | P45: =IFERROR(O45/$O$43,0) -> 0.64705882
B46: Medicamentos | D46: 20 | G46: 10 | O46: =SUM(C46:N46) -> 30 | P46: =IFERROR(O46/$O$43,0) -> 0.35294118
B47: Outros | O47: =SUM(C47:N47) -> 0 | P47: =IFERROR(O47/$O$43,0) -> 0
...

Sheet Gráficos
B3: [ PLANILHA ORÇAMENTO FAMILIAR ] - ANÁLISE GRÁFICA DE VALORES E GASTOS
V8: ='Orçamento'!B12 -> COMPOSIÇÃO RECEITA | W8: ='Orçamento'!O12 -> 3645
V9: ='Orçamento'!B22 -> HABITAÇÃO | W9: ='Orçamento'!O22 -> 1425 | X9: =W9/$W$17 -> 0.67248702
V10: ='Orçamento'!B34 -> EDUCAÇÃO | W10: ='Orçamento'!O34 -> 82 | X10: =W10/$W$17 -> 0.038697499
V11: ='Orçamento'!B43 -> SAÚDE | W11: ='Orçamento'!O43 -> 85 | X11: =W11/$W$17 -> 0.040113261
V12: ='Orçamento'!B50 -> TRANSPORTE | W12: ='Orçamento'!O50 -> 170 | X12: =W12/$W$17 -> 0.080226522
V13: ='Orçamento'!B60 -> DESPESAS PESSOAIS | W13: ='Orçamento'!O60 -> 87 | X13: =W13/$W$17 -> 0.041057102
V14: ='Orçamento'!B72 -> LAZER | W14: ='Orçamento'!O72 -> 65 | X14: =W14/$W$17 -> 0.030674847
V15: ='Orçamento'!B82 -> FINANCEIRO | W15: ='Orçamento'!O82 -> 90 | X15: =W15/$W$17 -> 0.042472865
V16: ='Orçamento'!B88 -> OUTROS | W16: ='Orçamento'!O88 -> 115 | X16: =W16/$W$17 -> 0.054270882
W17: =SUM(W9:W16) -> 2119
